Workbook

Sheet Variables
A1: Variable Name | B1: Definition
A2: POP | B2: Population, midperiod, thousands
A3: GDP | B3: GDP, millions of dollars
A4: GDP_QI | B4: GDP, chain-type quantity indexes for GDP, 2009=1
A5: GDP_P | B5: GDP, chain-type price indexes for GDP, 2009=1
A6: PCE | B6: Personal consumption expenditures, millions of current dollars
A7: PIE | B7: Private investment expenditures, millions of current dollars
A8: GCE | B8: Government consumption expenditures, millions of current dollars
A9: GIE | B9: Government investment expenditures, millions of current dollars
A10: NX | B10: Net exports, millions of dollars
A11: VA_TOT | B11: GDP, current prices, millions of dollars
A12: VA_GOOD | B12: Value added, current prices, goods, millions of dollars
... A47: X_TOT_P | B47: Chain-type price indexes for fixed investment, 1947=1
A48: From here below these are calculated by HRV
A49: VAX_S_GOOD | B49: Goods value added share in investment expenditure avergared over t and t-1
A50: VAX_S_SERV | B50: Services value added share in investment expenditure avergared over t and t-1
A51: VAC_S_GOOD | B51: Goods value added share in consumption expenditure avergared over t and t-1
A52: VAC_S_SERV | B52: Services value added share in consumption expenditure avergared over t and t-1
A53: VAX_GOOD_QI | B53: Goods quantity in investment expenditure, 1947 = 1
A54: VAX_SERV_QI | B54: Services quantity in investment expenditure, 1947 = 1
A55: VAC_GOOD_QI | B55: Goods quantity in consumption expenditure, 1947 = 1
A56: VAC_SERV_QI | B56: Services quantity iin consumption expenditure, 1947 = 1
A58: VA_SERV_GOOD_P | B58: Value added, services relative to goods price index, 1947 = 1
A59: VA_GOOD_X_P | B59: Value added, goods relative to investment price index, 1947 = 1
A60: VA_SERV_X_P | B60: Value added, services relative to investment price index, 1947 = 1
A61: C_X_P | B61: Consumption relative to investment price index, 1947 = 1
... A75: mLAB_S_SERV | B75: Average labour share, services sector

Sheet data
A1: year | B1: POP | C1: GDP | D1: GDP_QI | E1: GDP_P | F1: PCE | G1: PIE | H1: GCE | I1: GIE | J1: NX | K1: VA_TOT | L1: VA_GOOD | M1: VA_SERV | N1: VA_TOT_P | O1: VA_GOOD_P | P1: VA_SERV_P | Q1: VAX_GOOD | R1: VAC_GOOD | S1: VAX_SERV | T1: VAC_SERV | U1: LAB_TOT | V1: LAB_GOOD | W1: LAB_SERV | X1: LAB_S_TOT | Y1: VA_TOT_QI | Z1: VA_GOOD_QI | AA1: VA_SERV_QI | AB1: CAP_TOT_QI | AC1: CAP_GOOD_QI | AD1: CAP_SERV_QI | AE1: LAB_TOT_QI | AF1: LAB_GOOD_QI | AG1: LAB_SERV_QI | AH1: LAB_S_GOOD | AI1: LAB_S_SERV | AJ1: C_TOT | AK1: C_GOOD | AL1: C_SERV | AM1: C_TOT_QI | AN1: C_TOT_P | AO1: C_GOOD_QI | AP1: C_GOOD_P | AQ1: C_SERV_QI | AR1: C_SERV_P | AS1: X_TOT | AT1: X_TOT_QI | AU1: X_TOT_P | AV1: From here onwards | AW1: VAX_GOOD_S | AX1: VAX_SERV_S | AY1: VAC_GOOD_S | AZ1: VAC_SERV_S | BA1: C_PC | BB1: VAX_GOOD_S_hat | BC1: VAX_SERV_S_hat | BD1: omega_x | BE1: epsilon_x | BF1: VAX_GOOD_QI_hat | BG1: VAX_SERV_QI_hat | BH1: VAX_SERV_GOOD_hat | BI1: dVAX_SERV_S_hat_2017 | BJ1: VAC_GOOD_S_CES_hat | BK1: VAC_SERV_S_CES_hat | BL1: omega_c | BM1: epsilon_c | BN1: VAC_GOOD_CES_QI_hat | BO1: VAC_SERV_CES_QI_hat | BP1: VAC_SERV_GOOD_CES_hat | BQ1: dVAC_SERV_S_CES_hat_2017 | BR1: VAC_GOOD_S_PIGL_hat | BS1: VAC_SERV_S_PIGL_hat | BT1: chi | BU1: gamma | BV1: nu | BW1: VAC_GOOD_PIGL_QI_hat | BX1: VAC_SERV_PIGL_QI_hat | BY1: VAC_SERV_GOOD_PIGL_hat | BZ1: dVAC_SERV_S_PIGL_hat_2017 | CA1: VAX_S_GOOD | CB1: VAX_S_SERV | CC1: VAC_S_GOOD | CD1: VAC_S_SERV | CE1: VAX_GOOD_QI | CF1: VAX_SERV_QI | CG1: VAC_GOOD_QI | CH1: VAC_SERV_QI | CI1: VA_SERV_GOOD_P | CJ1: VA_SERV_X_P | CK1: VA_GOOD_X_P | CL1: C_X_P | CM1: mLAB_S_TOT | CN1: mLAB_S_GOOD | CO1: mLAB_S_SERV | CP1: dlTFPVA_TOT_I | CQ1: dlTFPVA_GOOD_I | CR1: dlTFPVA_SERV_I | CS1: TFPVA_TOT_I | CT1: TFPVA_GOOD_I | CU1: TFPVA_SERV_I | CV1: A_X_I | CW1: calA_X_I_BU | CX1: calA_C_I | CY1: calA_X_I_TD
A2: 1947 | B2: 144126 | C2: 249616 | D2: 1 | E2: 1 | F2: 161852 | G2: 37131 | H2: 34141 | I2: 5686 | J2: 10807 | K2: 244136 | L2: 101174.5 | M2: 142961.5 | N2: 1 | O2: 1 | P2: 1 | Q2: 27728 | R2: 71830 | S2: 15639 | T2: 128939 | U2: 128228.3 | V2: 62056.7 | W2: 66171.6 | Y2: 1 | Z2: 1 | AA2: 1 | AB2: 1 | AC2: 1 | AD2: 1 | AE2: 1 | AF2: 1 | AG2: 1 | AJ2: 200769 | AK2: 106106 | AL2: 94663 | AM2: 1 | AN2: 1 | AO2: 1 | AP2: 1 | AQ2: 1 | AR2: 1 | AS2: 43367 | AT2: 1 | AU2: 1 | AV2: these data are calculated | AW2: 0.6393802 | AX2: 0.3606198 | AY2: 0.3577743 | AZ2: 0.6422257 | BA2: 1.39301 | BB2: 0.6472423 | BC2: 0.3527577 | BD2: 0.6472423 | BE2: 0 | BF2: 1 | BG2: 1 | BH2: 1 | BI2: 0.8305648 | BJ2: 0.2911748 | BK2: 0.7088252 | BL2: 0.2911748 | BM2: 3.93e-15 | BN2: 1 | BO2: 1 | BP2: 1 | BQ2: 0.4489016 | BR2: 0.368622 | BS2: 0.6313779 | BT2: 0.5549737 | BU2: 0.6968653 | BV2: 0.4430698 | BW2: 1 | BX2: 1 | BY2: 1 | BZ2: 0 | CA2: . | CB2: . | CC2: . | CD2: . | CE2: 1 | CF2: 1 | CG2: 1 | CH2: 1 | CI2: 1 | CJ2: 1 | CK2: 1 | CL2: 1 | CM2: 0.563502 | CN2: 0.60515 | CO2: 0.5378623 | CP2: . | CQ2: . | CR2: . | CS2: 1 | CT2: 1 | CU2: 1 | CV2: 1 | CW2: 1 | CX2: 1 | CY2: 1
A3: 1948 | B3: 146631 | C3: 274468 | D3: 1.04119 | E3: 1.05606 | F3: 174878 | G3: 50347 | H3: 35274 | I3: 8482 | J3: 5487 | K3: 268064.5 | L3: 116470.8 | M3: 151593.7 | N3: 1.05517 | O3: 1.0567 | P3: 1.05405 | Q3: 34947 | R3: 79488 | S3: 18223 | T3: 135406.5 | U3: 141262.3 | V3: 70286.9 | W3: 70975.4 | X3: 0.5261 | Y3: 1.0406 | Z3: 1.08942 | AA3: 1.00601 | AB3: 1.03556 | AC3: 1.06134 | AD3: 1.0219 | AE3: 1.02442 | AF3: 1.01999 | AG3: 1.02872 | AH3: 0.60842 | AI3: 0.46553 | AJ3: 214894.5 | AK3: 115350 | AL3: 99544.5 | AM3: 1.02185 | AN3: 1.05003 | AO3: 0.97698 | AP3: 1.11544 | AQ3: 1.00919 | AR3: 1.04454 | AS3: 53170 | AT3: 1.13177 | AU3: 1.0833 | AV3: by HRV | AW3: 0.6572691 | AX3: 0.3427308 | AY3: 0.3698932 | AZ3: 0.6301068 | BA3: 1.465546 | BB3: 0.6478152 | BC3: 0.3521848 | BD3: 0.6472423 | BE3: 0 | BF3: 1.013821 | BG3: 1.013821 | BH3: 1 | BI3: 0.8305648 | BJ3: 0.2916931 | BK3: 0.7083069 | BL3: 0.2911748 | BM3: 3.93e-15 | BN3: 1.014727 | BO3: 1.014727 | BP3: 1 | BQ3: 0.4489016 | BR3: 0.3696528 | BS3: 0.6303472 | BT3: 0.5549737 | BU3: 0.6968653 | BV3: 0.4430698 | BW3: 1.015757 | BX3: 1.013812 | BY3: 0.9980855 | BZ3: 0 | CA3: 0.6483247 | CB3: 0.3516753 | CC3: 0.3638338 | CD3: 0.6361662 | CE3: 1.192723 | CF3: 1.105476 | CG3: 1.047235 | CH3: 0.9963078 | CI3: 0.9974932 | CJ3: 0.9730005 | CK3: 0.9754457 | CL3: 0.9692854 | CM3: 0.563502 | CN3: 0.60515 | CO3: 0.5378623 | CP3: 0.0109456 | CQ3: 0.0485082 | CR3: -0.0194236 | CS3: 1.011006 | CT3: 1.049704 | CU3: 0.9807639 | CV3: 0.9745877 | CW3: 0.9982752 | CX3: 0.9998848 | CY3: 0.9847559
A4: 1949 | B4: 149188 | C4: 272475 | D4: 1.03528 | E4: 1.05437 | F4: 178333 | G4: 39099 | H4: 38493 | I4: 11315 | J4: 5235 | K4: 266020.9 | L4: 109193.9 | M4: 156827 | N4: 1.05384 | O4: 1.01902 | P4: 1.08005 | Q4: 34250 | R4: 73387 | S4: 18856 | T4: 139527.9 | U4: 144455.8 | V4: 68189.2 | W4: 76266.5 | X4: 0.535 | Y4: 1.03397 | Z4: 1.05912 | AA4: 1.01568 | AB4: 1.06183 | AC4: 1.08348 | AD4: 1.05031 | AE4: 0.98833 | AF4: 0.95075 | AG4: 1.02515 | AH4: 0.61398 | AI4: 0.47725 | AJ4: 212914.9 | AK4: 107470 | AL4: 105444.9 | AM4: 1.01867 | AN4: 1.04412 | AO4: 1.0068 | AP4: 1.00897 | AQ4: 1.04381 | AR4: 1.07027 | AS4: 53106 | AT4: 1.11341 | AU4: 1.09984 | AW4: 0.6449366 | AX4: 0.3550635 | AY4: 0.3446777 | AZ4: 0.6553224 | BA4: 1.427158 | BB4: 0.6338506 | BC4: 0.3661494 | BD4: 0.6472423 | BE4: 0 | BF4: 1.01917 | BG4: 1.01917 | BH4: 1 | BI4: 0.8305648 | BJ4: 0.2793169 | BK4: 0.7206831 | BL4: 0.2911748 | BM4: 3.93e-15 | BN4: 0.998321 | BO4: 0.9983211 | BP4: 1 | BQ4: 0.4489016 | BR4: 0.3645028 | BS4: 0.6354972 | BT4: 0.5549737 | BU4: 0.6968653 | BV4: 0.4430698 | BW4: 1.029073 | BX4: 0.9883011 | BY4: 0.9603797 | BZ4: 0 | CA4: 0.6511028 | CB4: 0.3488972 | CC4: 0.3572854 | CD4: 0.6427146 | CE4: 1.212159 | CF4: 1.11634 | CG4: 1.002607 | CH4: 1.001918 | CI4: 1.059892 | CJ4: 0.9820117 | CK4: 0.9265202 | CL4: 0.9493455 | CM4: 0.563502 | CN4: 0.60515 | CO4: 0.5378623 | CP4: 0.0028929 | CQ4: 0.0023921 | CR4: -0.0004365 | CS4: 1.013935 | CT4: 1.052218 | CU4: 0.9803358 | CV4: 0.9455105 | CW4: 0.9697987 | CX4: 1.000232 | CY4: 0.9715313
A5: 1950 | B5: 151684 | C5: 299827 | D5: 1.12525 | E5: 1.06745 | F5: 192044 | G5: 56530 | H5: 39059 | I5: 11455 | J5: 738 | K5: 293337.2 | L5: 124854.9 | M5: 168482.4 | N5: 1.07587 | O5: 1.05214 | P5: 1.09373 | Q5: 40281 | R5: 82869 | S5: 21935 | T5: 148252.2 | U5: 153536.1 | V5: 73332.3 | W5: 80203.8 | X5: 0.53322 | Y5: 1.1168 | Z5: 1.1729 | AA5: 1.07752 | AB5: 1.09954 | AC5: 1.12103 | AD5: 1.08811 | AE5: 1.02903 | AF5: 1.0109 | AG5: 1.04729 | AH5: 0.60591 | AI5: 0.48117 | AJ5: 231121.2 | AK5: 120342 | AL5: 110779.2 | AM5: 1.09084 | AN5: 1.05612 | AO5: 1.05296 | AP5: 1.07795 | AQ5: 1.07026 | AR5: 1.09426 | AS5: 62216 | AT5: 1.28382 | AU5: 1.11748 | AW5: 0.6474379 | AX5: 0.352562 | AY5: 0.3585521 | AZ5: 0.6414479 | BA5: 1.523702 | BB5: 0.6383421 | BC5: 0.3616579 | BD5: 0.6472423 | BE5: 0 | BF5: 1.079086 | BG5: 1.079086 | BH5: 1 | BI5: 0.8305648 | BJ5: 0.2832395 | BK5: 0.7167605 | BL5: 0.2911748 | BM5: 3.93e-15 | BN5: 1.064313 | BO5: 1.064313 | BP5: 1 | BQ5: 0.4489016 | BR5: 0.3587807 | BS5: 0.6412193 | BT5: 0.5549737 | BU5: 0.6968653 | BV5: 0.4430698 | BW5: 1.06492 | BX5: 1.068936 | BY5: 1.00377 | BZ5: 0 | CA5: 0.6461872 | CB5: 0.3538128 | CC5: 0.3516149 | CD5: 0.6483851 | CE5: 1.380727 | CF5: 1.282389 | CG5: 1.09651 | CH5: 1.051255 | CI5: 1.039525 | CJ5: 0.9787431 | CK5: 0.9415293 | CL5: 0.9450923 | CM5: 0.563502 | CN5: 0.60515 | CO5: 0.5378623 | CP5: 0.0390806 | CQ5: 0.0526009 | CR5: 0.0316289 | CS5: 1.054344 | CT5: 1.109047 | CU5: 1.011838 | CV5: 0.9542536 | CW5: 1.023622 | CX5: 1.038339 | CY5: 1.015088
A6: 1951 | B6: 154287 | C6: 346914 | D6: 1.21577 | E6: 1.14313 | F6: 208339 | G6: 62759 | H6: 53722 | I6: 19582 | J6: 2513 | K6: 339441.1 | L6: 147250.9 | M6: 192190.2 | N6: 1.16746 | O6: 1.1688 | P6: 1.16604 | Q6: 48549 | R6: 96818 | S6: 23881 | T6: 170193.1 | U6: 174406.8 | V6: 86367.1 | W6: 88039.7 | X6: 0.51861 | Y6: 1.19094 | Z6: 1.24522 | AA6: 1.15292 | AB6: 1.15156 | AC6: 1.19013 | AD6: 1.13058 | AE6: 1.09934 | AF6: 1.07845 | AG6: 1.12034 | AH6: 0.58694 | AI6: 0.46706 | AJ6: 267011.1 | AK6: 133976 | AL6: 133035.1 | AM6: 1.1825 | AN6: 1.12544 | AO6: 1.06265 | AP6: 1.18903 | AQ6: 1.22704 | AR6: 1.14609 | AS6: 72430 | AT6: 1.36975 | AU6: 1.21932 | AW6: 0.6702886 | AX6: 0.3297114 | AY6: 0.3625992 | AZ6: 0.6374008 | BA6: 1.730613 | BB6: 0.6477833 | BC6: 0.3522167 | BD6: 0.6472423 | BE6: 0 | BF6: 1.138818 | BG6: 1.138818 | BH6: 1 | BI6: 0.8305648 | BJ6: 0.2916643 | BK6: 0.7083358 | BL6: 0.2911748 | BM6: 3.93e-15 | BN6: 1.13978 | BO6: 1.13978 | BP6: 1 | BQ6: 0.4489016 | BR6: 0.3564659 | BS6: 0.6435341 | BT6: 0.5549737 | BU6: 0.6968653 | BV6: 0.4430698 | BW6: 1.100343 | BX6: 1.162527 | BY6: 1.056513 | BZ6: 0 | CA6: 0.6588632 | CB6: 0.3411368 | CC6: 0.3605756 | CD6: 0.6394243 | CE6: 1.498031 | CF6: 1.30958 | CG6: 1.153212 | CH6: 1.131999 | CI6: 0.9976326 | CJ6: 0.9562985 | CK6: 0.9585679 | CL6: 0.9230083 | CM6: 0.563502 | CN6: 0.60515 | CO6: 0.5378623 | CP6: 0.0068614 | CQ6: -0.0027284 | CR6: 0.0129287 | CS6: 1.061603 | CT6: 1.106025 | CU6: 1.025005 | CV6: 0.9579909 | CW6: 1.03082 | CX6: 1.047345 | CY6: 1.016448
A7: 1952 | B7: 156954 | C7: 367341 | D7: 1.26543 | E7: 1.16295 | F7: 219320 | G7: 57274 | H7: 64963 | I7: 24621 | J7: 1164 | K7: 359559.4 | L7: 151906.8 | M7: 207652.6 | N7: 1.19152 | O7: 1.15432 | P7: 1.21972 | Q7: 52704 | R7: 97519 | S7: 25676 | T7: 183660.4 | U7: 184289.9 | V7: 90294.4 | W7: 93995.5 | X7: 0.51317 | Y7: 1.23605 | Z7: 1.30071 | AA7: 1.19085 | AB7: 1.19948 | AC7: 1.2408 | AD7: 1.177 | AE7: 1.1224 | AF7: 1.0965 | AG7: 1.14847 | AH7: 0.59047 | AI7: 0.45537 | AJ7: 281179.4 | AK7: 131277 | AL7: 149902.4 | AM7: 1.22556 | AN7: 1.14318 | AO7: 1.07811 | AP7: 1.14801 | AQ7: 1.34046 | AR7: 1.18177 | AS7: 78380 | AT7: 1.44859 | AU7: 1.24767 | AW7: 0.6724164 | AX7: 0.3275836 | AY7: 0.3468213 | AZ7: 0.6531787 | BA7: 1.791476 | BB7: 0.63456 | BC7: 0.36544 | BD7: 0.6472423 | BE7: 0 | BF7: 1.189502 | BG7: 1.189502 | BH7: 1 | BI7: 0.8305648 | BJ7: 0.2799329 | BK7: 0.7200671 | BL7: 0.2911748 | BM7: 3.93e-15 | BN7: 1.166432 | BO7: 1.166432 | BP7: 1 | BQ7: 0.4489016 | BR7: 0.3444615 | BS7: 0.6555384 | BT7: 0.5549737 | BU7: 0.6968653 | BV7: 0.4430698 | BW7: 1.133754 | BX7: 1.19216 | BY7: 1.051515 | BZ7: 0 | CA7: 0.6713525 | CB7: 0.3286475 | CC7: 0.3547103 | CD7: 0.6452897 | CE7: 1.646636 | CF7: 1.346038 | CG7: 1.176132 | CH7: 1.167804 | CI7: 1.056656 | CJ7: 0.9775965 | CK7: 0.9251794 | CL7: 0.916245 | CM7: 0.563502 | CN7: 0.60515 | CO7: 0.5378623 | CP7: 0.0076823 | CQ7: 0.0160435 | CR7: 0.0008263 | CS7: 1.06979 | CT7: 1.123913 | CU7: 1.025852 | CV7: 0.9422551 | CW7: 1.024468 | CX7: 1.052593 | CY7: 1.021645
A8: 1953 | B8: 159565 | C8: 389218 | D8: 1.32482 | E8: 1.17697 | F8: 232740 | G8: 60414 | H8: 70099 | I8: 26666 | J8: -701 | K8: 380859.3 | L8: 160699.7 | M8: 220159.5 | N8: 1.20175 | O8: 1.14078 | P8: 1.24862 | Q8: 57343 | R8: 101806 | S8: 27789 | T8: 193921.3 | U8: 202171.1 | V8: 100464.4 | W8: 101706.7 | X8: 0.52169 | Y8: 1.29813 | Z8: 1.39234 | AA8: 1.23335 | AB8: 1.25268 | AC8: 1.29971 | AD8: 1.22727 | AE8: 1.14755 | AF8: 1.12556 | AG8: 1.16965 | AH8: 0.60979 | AI8: 0.45731 | AJ8: 295727.3 | AK8: 134421 | AL8: 161306.3 | AM8: 1.27082 | AN8: 1.16017 | AO8: 1.12034 | AP8: 1.13184 | AQ8: 1.39697 | AR8: 1.22093 | AS8: 85132 | AT8: 1.57033 | AU8: 1.25009 | AW8: 0.6735775 | AX8: 0.3264225 | AY8: 0.3442564 | AZ8: 0.6557436 | BA8: 1.853334 | BB8: 0.6263545 | BC8: 0.3736455 | BD8: 0.6472423 | BE8: 0 | BF8: 1.249533 | BG8: 1.249533 | BH8: 1 | BI8: 0.8305648 | BJ8: 0.2728887 | BK8: 0.7271113 | BL8: 0.2911748 | BM8: 3.93e-15 | BN8: 1.210114 | BO8: 1.210114 | BP8: 1 | BQ8: 0.4489016 | BR8: 0.3341513 | BS8: 0.6658487 | BT8: 0.5549737 | BU8: 0.6968653 | BV8: 0.4430698 | BW8: 1.170459 | BX8: 1.244087 | BY8: 1.062905 | BZ8: 0 | CA8: 0.6729969 | CB8: 0.327003 | CC8: 0.3455389 | CD8: 0.6544611 | CE8: 1.812849 | CF8: 1.423094 | CG8: 1.242417 | CH8: 1.204511 | CI8: 1.094536 | CJ8: 0.998824 | CK8: 0.9125549 | CL8: 0.9280661 | CM8: 0.563502 | CN8: 0.60515 | CO8: 0.5378623 | CP8: 0.0175754 | CQ8: 0.0330877 | CR8: 0.0065195 | CS8: 1.088758 | CT8: 1.161723 | CU8: 1.032562 | CV8: 0.9401638 | CW8: 1.046052 | CX8: 1.067108 | CY8: 1.046656
A9: 1954 | B9: 162391 | C9: 390549 | D9: 1.31715 | E9: 1.18786 | F9: 239608 | G9: 58070 | H9: 67071 | I9: 25396 | J9: 404 | K9: 382379.5 | L9: 155580.9 | M9: 226798.6 | N9: 1.20913 | O9: 1.13485 | P9: 1.26641 | Q9: 56328 | R9: 97746 | S9: 29075 | T9: 199230.5 | U9: 197065.8 | V9: 94278.4 | W9: 102787.3 | X9: 0.5231 | Y9: 1.29535 | Z9: 1.35503 | AA9: 1.2527 | AB9: 1.3127 | AC9: 1.36591 | AD9: 1.28423 | AE9: 1.1093 | AF9: 1.05368 | AG9: 1.16575 | AH9: 0.61557 | AI9: 0.45759 | AJ9: 296976.5 | AK9: 132753 | AL9: 164223.5 | AM9: 1.2616 | AN9: 1.17272 | AO9: 1.14503 | AP9: 1.0929 | AQ9: 1.38261 | AR9: 1.255 | AS9: 85403 | AT9: 1.56955 | AU9: 1.2547 | AW9: 0.6595553 | AX9: 0.3404447 | AY9: 0.3291371 | AZ9: 0.6708629 | BA9: 1.828774 | BB9: 0.6218126 | BC9: 0.3781874 | BD9: 0.6472423 | BE9: 0 | BF9: 1.25222 | BG9: 1.252221 | BH9: 1 | BI9: 0.8305648 | BJ9: 0.2690643 | BK9: 0.7309357 | BL9: 0.2911748 | BM9: 3.93e-15 | BN9: 1.204454 | BO9: 1.204454 | BP9: 1 | BQ9: 0.4489016 | BR9: 0.3347415 | BS9: 0.6652585 | BT9: 0.5549737 | BU9: 0.6968653 | BV9: 0.4430698 | BW9: 1.183631 | BX9: 1.230698 | BY9: 1.039764 | BZ9: 0 | CA9: 0.6665664 | CB9: 0.3334336 | CC9: 0.3366968 | CD9: 0.6633032 | CE9: 1.790064 | CF9: 1.468032 | CG9: 1.199101 | CH9: 1.220103 | CI9: 1.115932 | CJ9: 1.009335 | CK9: 0.9044773 | CL9: 0.9346637 | CM9: 0.563502 | CN9: 0.60515 | CO9: 0.5378623 | CP9: -0.0034734 | CQ9: -0.0116544 | CR9: -0.0023594 | CS9: 1.084983 | CT9: 1.148262 | CU9: 1.030129 | CV9: 0.937875 | CW9: 1.035055 | CX9: 1.061941 | CY9: 1.045582
A10: 1955 | B10: 165275 | C10: 425478 | D10: 1.41111 | E10: 1.20793 | F10: 258288 | G10: 73754 | H10: 68600 | I10: 24358 | J10: 478 | K10: 416129 | L10: 170891.4 | M10: 245237.5 | N10: 1.22688 | O10: 1.14062 | P10: 1.29347 | Q10: 60978 | R10: 108469 | S10: 32147 | T10: 214535 | U10: 222725.8 | V10: 105471.1 | W10: 117254.6 | X10: 0.5253 | Y10: 1.38929 | Z10: 1.48083 | AA10: 1.32621 | AB10: 1.36865 | AC10: 1.41756 | AD10: 1.34208 | AE10: 1.14721 | AF10: 1.10264 | AG10: 1.19271 | AH10: 0.61158 | AI10: 0.46567 | AJ10: 323004 | AK10: 150914 | AL10: 172090 | AM10: 1.35134 | AN10: 1.19246 | AO10: 1.24976 | AP10: 1.13988 | AQ10: 1.4096 | AR10: 1.29174 | AS10: 93125 | AT10: 1.68262 | AU10: 1.2762 | AW10: 0.6547973 | AX10: 0.3452027 | AY10: 0.3358132 | AZ10: 0.6641868 | BA10: 1.954343 | BB10: 0.6180287 | BC10: 0.3819713 | BD10: 0.6472423 | BE10: 0 | BF10: 1.346822 | BG10: 1.346822 | BH10: 1 | BI10: 0.8305648 | BJ10: 0.2659176 | BK10: 0.7340825 | BL10: 0.2911748 | BM10: 3.93e-15 | BN10: 1.288136 | BO10: 1.288136 | BP10: 1 | BQ10: 0.4489016 | BR10: 0.3228034 | BS10: 0.6771966 | BT10: 0.5549737 | BU10: 0.6968653 | BV10: 0.4430698 | BW10: 1.235166 | BX10: 1.334078 | BY10: 1.08008 | BZ10: 0 | CA10: 0.6571763 | CB10: 0.3428237 | CC10: 0.3324752 | CD10: 0.6675248 | CE10: 1.928022 | CF10: 1.589191 | CG10: 1.323906 | CH10: 1.286348 | CI10: 1.133999 | CJ10: 1.013526 | CK10: 0.893763 | CL10: 0.9343781 | CM10: 0.563502 | CN10: 0.60515 | CO10: 0.5378623 | CP10: 0.0328565 | CQ10: 0.0469892 | CR10: 0.024911 | CS10: 1.121224 | CT10: 1.203506 | CU10: 1.056113 | CV10: 0.9318816 | CW10: 1.068901 | CX10: 1.095167 | CY10: 1.077893
A11: 1956 | B11: 168221 | C11: 449353 | D11: 1.44113 | E11: 1.24915 | F11: 271128 | G11: 77685 | H11: 71034 | I11: 27146 | J11: 2361 | K11: 439820.3 | L11: 179118 | M11: 260702.3 | N11: 1.27597 | O11: 1.19561 | P11: 1.33792 | Q11: 66152 | R11: 111503 | S11: 34729 | T11: 227436.3 | U11: 236725 | V11: 110789.3 | W11: 125935.7 | X11: 0.53673 | Y11: 1.4119 | Z11: 1.48074 | AA11: 1.363 | AB11: 1.43503 | AC11: 1.49208 | AD11: 1.4044 | AE11: 1.17311 | AF11: 1.1196 | AG11: 1.22733 | AH11: 0.61785 | AI11: 0.4806 | AJ11: 338939.3 | AK11: 156457 | AL11: 182482.3 | AM11: 1.38106 | AN11: 1.22339 | AO11: 1.28053 | AP11: 1.15243 | AQ11: 1.44773 | AR11: 1.33261 | AS11: 100881 | AT11: 1.71416 | AU11: 1.35706 | AW11: 0.6557429 | AX11: 0.3442571 | AY11: 0.3289763 | AZ11: 0.6710237 | BA11: 2.014845 | BB11: 0.6211616 | BC11: 0.3788384 | BD11: 0.6472423 | BE11: 0 | BF11: 1.355104 | BG11: 1.355104 | BH11: 1 | BI11: 0.8305648 | BJ11: 0.2685204 | BK11: 0.7314796 | BL11: 0.2911748 | BM11: 3.93e-15 | BN11: 1.302142 | BO11: 1.302142 | BP11: 1 | BQ11: 0.4489016 | BR11: 0.3264049 | BS11: 0.6735951 | BT11: 0.5549737 | BU11: 0.6968653 | BV11: 0.4430698 | BW11: 1.250288 | BX11: 1.346185 | BY11: 1.076699 | BZ11: 0 | CA11: 0.6552701 | CB11: 0.3447299 | CC11: 0.3323947 | CD11: 0.6676052 | CE11: 1.995419 | CF11: 1.65979 | CG11: 1.298345 | CH11: 1.318395 | CI11: 1.119025 | CJ11: 0.985895 | CK11: 0.8810307 | CL11: 0.9014971 | CM11: 0.563502 | CN11: 0.60515 | CO11: 0.5378623 | CP11: -0.0171114 | CQ11: -0.0310343 | CR11: -0.0085736 | CS11: 1.102202 | CT11: 1.166729 | CU11: 1.047097 | CV11: 0.9144065 | CW11: 1.025533 | CX11: 1.079321 | CY11: 1.036337
A12: 1957 | B12: 171274 | C12: 474039 | D12: 1.47154 | E12: 1.29053 | F12: 286296 | G12: 76505 | H12: 76933 | I12: 30230 | J12: 4075 | K12: 463620.3 | L12: 185726.9 | M12: 277893.4 | N12: 1.31886 | O12: 1.23571 | P12: 1.38297 | Q12: 69278 | R12: 114808 | S12: 36679 | T12: 242855.3 | U12: 253734.3 | V12: 117129.3 | W12: 136605 | X12: 0.54276 | Y12: 1.43989 | Z12: 1.48555 | AA12: 1.40555 | AB12: 1.49919 | AC12: 1.56315 | AD12: 1.46516 | AE12: 1.17253 | AF12: 1.10034 | AG12: 1.24481 | AH12: 0.62459 | AI12: 0.48732 | AJ12: 357663.3 | AK12: 161933 | AL12: 195730.3 | AM12: 1.41321 | AN12: 1.26283 | AO12: 1.31018 | AP12: 1.16691 | AQ12: 1.50029 | AR12: 1.38062 | AS12: 105957 | AT12: 1.73747 | AU12: 1.40622 | AW12: 0.6538312 | AX12: 0.3461687 | AY12: 0.3209947 | AZ12: 0.6790053 | BA12: 2.088252 | BB12: 0.6211308 | BC12: 0.3788692 | BD12: 0.6472423 | BE12: 0 | BF12: 1.383492 | BG12: 1.383492 | BH12: 1 | BI12: 0.8305648 | BJ12: 0.2684946 | BK12: 0.7315054 | BL12: 0.2911748 | BM12: 3.93e-15 | BN12: 1.329359 | BO12: 1.329359 | BP12: 1 | BQ12: 0.4489016 | BR12: 0.3258927 | BS12: 0.6741073 | BT12: 0.5549737 | BU12: 0.6968653 | BV12: 0.4430698 | BW12: 1.274541 | BX12: 1.37532 | BY12: 1.07907 | BZ12: 0 | CA12: 0.6547871 | CB12: 0.3452129 | CC12: 0.3249855 | CD12: 0.6750145 | CE12: 2.0219 | CF12: 1.695879 | CG12: 1.293449 | CH12: 1.361914 | CI12: 1.119171 | CJ12: 0.9834692 | CK12: 0.8787476 | CL12: 0.8980339 | CM12: 0.563502 | CN12: 0.60515 | CO12: 0.5378623 | CP12: 0.0008206 | CQ12: -0.0072896 | CR12: 0.0042825 | CS12: 1.103106 | CT12: 1.158255 | CU12: 1.051591 | CV12: 0.9120783 | CW12: 1.019926 | CX12: 1.080566 | CY12: 1.034581
A13: 1958 | B13: 174141 | C13: 481229 | D13: 1.46061 | E13: 1.31992 | F13: 295606 | G13: 70947 | H13: 81516 | I13: 32622 | J13: 538 | K13: 470428.9 | L13: 181038.2 | M13: 289390.7 | N13: 1.34797 | O13: 1.25777 | P13: 1.41728 | Q13: 66359 | R13: 112824 | S13: 37576 | T13: 253669.9 | U13: 259092.8 | V13: 114589.2 | W13: 144503.6 | X13: 0.54902 | Y13: 1.42949 | Z13: 1.42265 | AA13: 1.42827 | AB13: 1.55376 | AC13: 1.60313 | AD13: 1.52604 | AE13: 1.13188 | AF13: 1.02297 | AG13: 1.23952 | AH13: 0.6318 | AI13: 0.49546 | AJ13: 366493.9 | AK13: 159951 | AL13: 206542.9 | AM13: 1.40881 | AN13: 1.29848 | AO13: 1.2714 | AP13: 1.18818 | AQ13: 1.53436 | AR13: 1.42502 | AS13: 103935 | AT13: 1.69816 | AU13: 1.41131 | AW13: 0.6384664 | AX13: 0.3615336 | AY13: 0.3078469 | AZ13: 0.6921531 | BA13: 2.104581 | BB13: 0.6195279 | BC13: 0.3804721 | BD13: 0.6472423 | BE13: 0 | BF13: 1.389191 | BG13: 1.389191 | BH13: 1 | BI13: 0.8305648 | BJ13: 0.2671601 | BK13: 0.7328399 | BL13: 0.2911748 | BM13: 3.93e-15 | BN13: 1.331636 | BO13: 1.331636 | BP13: 1 | BQ13: 0.4489016 | BR13: 0.327373 | BS13: 0.672627 | BT13: 0.5549737 | BU13: 0.6968653 | BV13: 0.4430698 | BW13: 1.288931 | BX13: 1.372147 | BY13: 1.064562 | BZ13: 0 | CA13: 0.6461488 | CB13: 0.3538512 | CC13: 0.3144208 | CD13: 0.6855792 | CE13: 1.902739 | CF13: 1.695302 | CG13: 1.248802 | CH13: 1.38813 | CI13: 1.126814 | CJ13: 1.004226 | CK13: 0.8912087 | CL13: 0.9200503 | CM13: 0.563502 | CN13: 0.60515 | CO13: 0.5378623 | CP13: -0.0029728 | CQ13: -0.0131996 | CR13: 0.0006683 | CS13: 1.099832 | CT13: 1.143067 | CU13: 1.052294 | CV13: 0.9272407 | CW13: 1.028598 | CX13: 1.077202 | CY13: 1.050471
A14: 1959 | B14: 177130 | C14: 521654 | D14: 1.56191 | E14: 1.338 | F14: 317130 | G14: 85669 | H14: 82594 | I14: 35863 | J14: 397 | K14: 509054.2 | L14: 196703.9 | M14: 312350.3 | N14: 1.37105 | O14: 1.27481 | P14: 1.44474 | Q14: 74932 | R14: 119779 | S14: 42683 | T14: 271660.2 | U14: 275964.8 | V14: 124572.5 | W14: 151392.3 | X14: 0.54644 | Y14: 1.52082 | Z14: 1.5251 | AA14: 1.51228 | AB14: 1.61254 | AC14: 1.63881 | AD14: 1.59466 | AE14: 1.17106 | AF14: 1.07984 | AG14: 1.26179 | AH14: 0.63313 | AI14: 0.49201 | AJ14: 391439.2 | AK14: 172131 | AL14: 219308.2 | AM14: 1.48659 | AN14: 1.31777 | AO14: 1.3313 | AP14: 1.22436 | AQ14: 1.59967 | AR14: 1.45514 | AS14: 117615 | AT14: 1.90337 | AU14: 1.42489 | AW14: 0.6370956 | AX14: 0.3629044 | AY14: 0.3059964 | AZ14: 0.6940036 | BA14: 2.209898 | BB14: 0.6181739 | BC14: 0.3818261 | BD14: 0.6472423 | BE14: 0 | BF14: 1.460721 | BG14: 1.460722 | BH14: 1 | BI14: 0.8305648 | BJ14: 0.2660377 | BK14: 0.7339623 | BL14: 0.2911748 | BM14: 3.93e-15 | BN14: 1.397375 | BO14: 1.397375 | BP14: 0.9999999 | BQ14: 0.4489016 | BR14: 0.3207467 | BS14: 0.6792533 | BT14: 0.5549737 | BU14: 0.6968653 | BV14: 0.4430698 | BW14: 1.330775 | BX14: 1.451847 | BY14: 1.090979 | BZ14: 0 | CA14: 0.637781 | CB14: 0.362219 | CC14: 0.3069217 | CD14: 0.6930783 | CE14: 2.119848 | CF14: 1.889108 | CG14: 1.30807 | CH14: 1.458319 | CI14: 1.133301 | CJ14: 1.013931 | CK14: 0.8946708 | CL14: 0.924822 | CM14: 0.563502 | CN14: 0.60515 | CO14: 0.5378623 | CP14: 0.0265503 | CQ14: 0.0294442 | CR14: 0.0279218 | CS14: 1.129424 | CT14: 1.177224 | CU14: 1.08209 | CV14: 0.9327803 | CW14: 1.06506 | CX14: 1.108166 | CY14: 1.086752
A15: 1960 | B15: 180760 | C15: 542382 | D15: 1.60206 | E15: 1.3563 | F15: 331180 | G15: 86477 | H15: 84517 | I15: 36003 | J15: 4204 | K15: 529152.2 | L15: 200917.2 | M15: 328235 | N15: 1.3881 | O15: 1.27525 | P15: 1.47366 | Q15: 75851 | R15: 123039 | S15: 43397 | T15: 286865.2 | U15: 297053.8 | V15: 130059.3 | W15: 166994.5 | X15: 0.55174 | Y15: 1.56144 | Z15: 1.55723 | AA15: 1.558 | AB15: 1.67895 | AC15: 1.67949 | AD15: 1.67204 | AE15: 1.18679 | AF15: 1.07859 | AG15: 1.29368 | AH15: 0.64031 | AI15: 0.49673 | AJ15: 409904.2 | AK15: 179681 | AL15: 230223.2 | AM15: 1.53144 | AN15: 1.33964 | AO15: 1.38597 | AP15: 1.22774 | AQ15: 1.64013 | AR15: 1.49001 | AS15: 119248 | AT15: 1.92296 | AU15: 1.42995 | AW15: 0.6360778 | AX15: 0.3639222 | AY15: 0.3001653 | AZ15: 0.6998347 | BA15: 2.267671 | BB15: 0.6135668 | BC15: 0.3864332 | BD15: 0.6472423 | BE15: 0 | BF15: 1.517702 | BG15: 1.517702 | BH15: 1 | BI15: 0.8305648 | BJ15: 0.2622524 | BK15: 0.7377476 | BL15: 0.2911748 | BM15: 3.93e-15 | BN15: 1.441973 | BO15: 1.441973 | BP15: 1 | BQ15: 0.4489016 | BR15: 0.3153736 | BS15: 0.6846265 | BT15: 0.5549737 | BU15: 0.6968653 | BV15: 0.4430698 | BW15: 1.369732 | BX15: 1.502287 | BY15: 1.096774 | BZ15: 0 | CA15: 0.6365867 | CB15: 0.3634133 | CC15: 0.3030809 | CD15: 0.6969191 | CE15: 2.145106 | CF15: 1.883014 | CG15: 1.343207 | CH15: 1.50972 | CI15: 1.155588 | CJ15: 1.030568 | CK15: 0.8918124 | CL15: 0.9368412 | CM15: 0.563502 | CN15: 0.60515 | CO15: 0.5378623 | CP15: 0.0012238 | CQ15: 0.0107953 | CR15: -0.004963 | CS15: 1.130807 | CT15: 1.190002 | CU15: 1.076733 | CV15: 0.936404 | CW15: 1.074451 | CX15: 1.107425 | CY15: 1.097716
... A72: 2017 | B72: 326860 | C72: 19477336 | D72: 8.87794 | E72: 8.78911 | F72: 13233609 | G72: 3385624 | H72: 2726560 | I72: 668277 | J72: -536734 | K72: 18810856 | L72: 3794884 | M72: 15015973 | N72: 9.4144 | O72: 6.26142 | P72: 11.31823 | Q72: 1876510 | R72: 1798890 | S72: 2145202 | T72: 12990254 | U72: 10225408 | V72: 2023748.8 | W72: 8201659.5 | X72: 0.54299 | Y72: 8.18435 | Z72: 5.99038 | AA72: 9.28016 | AB72: 14.54005 | AC72: 9.05806 | AD72: 16.78096 | AE72: 2.77824 | AF72: 1.3913 | AG72: 3.88789 | AH72: 0.53727 | AI72: 0.54443 | AJ72: 14789144 | AK72: 3223072 | AL72: 11566072 | AM72: 7.95864 | AN72: 9.41576 | AO72: 7.92972 | AP72: 3.89692 | AQ72: 8.33922 | AR72: 14.90486 | AS72: 4021712 | AT72: 13.48012 | AU72: 6.87951 | AW72: 0.4665948 | AX72: 0.5334052 | AY72: 0.1216358 | AZ72: 0.8783641 | BA72: 45.24611 | BB72: 0.5037329 | BC72: 0.4962671 | BD72: 0.6472423 | BE72: 0 | BF72: 9.156017 | BG72: 9.156019 | BH72: 1 | BI72: 0.8305648 | BJ72: 0.1851719 | BK72: 0.8148281 | BL72: 0.2911748 | BM72: 3.93e-15 | BN72: 7.481601 | BO72: 7.481601 | BP72: 1 | BQ72: 0.4489016 | BR72: 0.1359313 | BS72: 0.8640686 | BT72: 0.5549737 | BU72: 0.6968653 | BV72: 0.4430698 | BW72: 4.33822 | BX72: 8.906898 | BY72: 2.053123 | BZ72: 0.9853994 | CA72: 0.4655028 | CB72: 0.5344972 | CC72: 0.1201121 | CD72: 0.8798879 | CE72: 10.80835 | CF72: 12.11938 | CG72: 3.999683 | CH72: 8.901324 | CI72: 1.807613 | CJ72: 1.645208 | CK72: 0.9101551 | CL72: 1.368667 | CM72: 0.563502 | CN72: 0.60515 | CO72: 0.5378623 | CP72: -0.0091473 | CQ72: 0.0068406 | CR72: -0.0132413 | CS72: 1.430414 | CT72: 1.900606 | CU72: 1.260725 | CV72: 1.171907 | CW72: 1.889104 | CX72: 1.397747 | CY72: 1.957476
AV73: From here onwards
A74: Average 1947-2010 | X74: =AVERAGE(X2:X72) -> 0.56350243 | AH74: =AVERAGE(AH2:AH72) -> 0.60514986 | AI74: =AVERAGE(AI2:AI72) -> 0.53786243
A75: Average 1980-2010 | X75: =AVERAGE(X35:X72) -> 0.57655737 | AH75: =AVERAGE(AH35:AH72) -> 0.58312184 | AI75: =AVERAGE(AI35:AI72) -> 0.57206763

Sheet TFP_Tot
A1: year | B1: VA_TOT_QI | C1: CAP_TOT_QI | D1: LAB_TOT_QI | F1: avg_LAB_S_TOT | H1: dl_chg_VA | I1: dl_chg_CAP | J1: dl_chg_LAB | K1: dl_chg_TFP | M1: Cum_Sum | N1: TFP_INDEX
A2: 1947 | B2: =data!Y2 -> 1 | C2: =data!AB2 -> 1 | D2: =data!AE2 -> 1 | F2: =data!X74 -> 0.56350243 | M2: 0 | N2: =EXP(M2) -> 1
A3: 1948 | B3: =data!Y3 -> 1.0406 | C3: =data!AB3 -> 1.03556 | D3: =data!AE3 -> 1.02442 | F3: =F2 -> 0.56350243 | H3: =LN(B3/B2) -> 0.03979747 | I3: =LN(C3/C2) -> 0.034942343 | J3: =LN(D3/D2) -> 0.024126599 | K3: =H3-(1-F3)*I3-F3*J3 -> 0.010949825 | M3: =M2+K3 -> 0.010949825 | N3: =EXP(M3) -> 1.01101
A4: 1949 | B4: =data!Y4 -> 1.03397 | C4: =data!AB4 -> 1.06183 | D4: =data!AE4 -> 0.98833 | F4: =F3 -> 0.56350243 | H4: =LN(B4/B3) -> -0.0063917077 | I4: =LN(C4/C3) -> 0.025051491 | J4: =LN(D4/D3) -> -0.035865228 | K4: =H4-(1-F4)*I4-F4*J4 -> 0.00288352 | M4: =M3+K4 -> 0.013833345 | N4: =EXP(M4) -> 1.0139295
A5: 1950 | B5: =data!Y5 -> 1.1168 | C5: =data!AB5 -> 1.09954 | D5: =data!AE5 -> 1.02903 | F5: =F4 -> 0.56350243 | H5: =LN(B5/B4) -> 0.077061691 | I5: =LN(C5/C4) -> 0.034898076 | J5: =LN(D5/D4) -> 0.04035524 | K5: =H5-(1-F5)*I5-F5*J5 -> 0.03908849 | M5: =M4+K5 -> 0.052921835 | N5: =EXP(M5) -> 1.0543472
A6: 1951 | B6: =data!Y6 -> 1.19094 | C6: =data!AB6 -> 1.15156 | D6: =data!AE6 -> 1.09934 | F6: =F5 -> 0.56350243 | H6: =LN(B6/B5) -> 0.064275458 | I6: =LN(C6/C5) -> 0.046225634 | J6: =LN(D6/D5) -> 0.066093389 | K6: =H6-(1-F6)*I6-F6*J6 -> 0.006854296 | M6: =M5+K6 -> 0.059776131 | N6: =EXP(M6) -> 1.0615989
A7: 1952 | B7: =data!Y7 -> 1.23605 | C7: =data!AB7 -> 1.19948 | D7: =data!AE7 -> 1.1224 | F7: =F6 -> 0.56350243 | H7: =LN(B7/B6) -> 0.0371779 | I7: =LN(C7/C6) -> 0.040770585 | J7: =LN(D7/D6) -> 0.02075925 | K7: =H7-(1-F7)*I7-F7*J7 -> 0.007683751 | M7: =M6+K7 -> 0.067459882 | N7: =EXP(M7) -> 1.0697873
A8: 1953 | B8: =data!Y8 -> 1.29813 | C8: =data!AB8 -> 1.25268 | D8: =data!AE8 -> 1.14755 | F8: =F7 -> 0.56350243 | H8: =LN(B8/B7) -> 0.049003956 | I8: =LN(C8/C7) -> 0.043397127 | J8: =LN(D8/D7) -> 0.022159985 | K8: =H8-(1-F8)*I8-F8*J8 -> 0.01757401 | M8: =M7+K8 -> 0.085033892 | N8: =EXP(M8) -> 1.088754
A9: 1954 | B9: =data!Y9 -> 1.29535 | C9: =data!AB9 -> 1.3127 | D9: =data!AE9 -> 1.1093 | F9: =F8 -> 0.56350243 | H9: =LN(B9/B8) -> -0.0021438384 | I9: =LN(C9/C8) -> 0.046800829 | J9: =LN(D9/D8) -> -0.033900049 | K9: =H9-(1-F9)*I9-F9*J9 -> -0.0034695264 | M9: =M8+K9 -> 0.081564366 | N9: =EXP(M9) -> 1.0849831
A10: 1955 | B10: =data!Y10 -> 1.38929 | C10: =data!AB10 -> 1.36865 | D10: =data!AE10 -> 1.14721 | F10: =F9 -> 0.56350243 | H10: =LN(B10/B9) -> 0.070011896 | I10: =LN(C10/C9) -> 0.041738768 | J10: =LN(D10/D9) -> 0.033603722 | K10: =H10-(1-F10)*I10-F10*J10 -> 0.032857247 | M10: =M9+K10 -> 0.11442161 | N10: =EXP(M10) -> 1.1212247
A11: 1956 | B11: =data!Y11 -> 1.4119 | C11: =data!AB11 -> 1.43503 | D11: =data!AE11 -> 1.17311 | F11: =F10 -> 0.56350243 | H11: =LN(B11/B10) -> 0.01614349 | I11: =LN(C11/C10) -> 0.047360902 | J11: =LN(D11/D10) -> 0.022325434 | K11: =H11-(1-F11)*I11-F11*J11 -> -0.017109866 | M11: =M10+K11 -> 0.097311747 | N11: =EXP(M11) -> 1.1022039
A12: 1957 | B12: =data!Y12 -> 1.43989 | C12: =data!AB12 -> 1.49919 | D12: =data!AE12 -> 1.17253 | F12: =F11 -> 0.56350243 | H12: =LN(B12/B11) -> 0.019630407 | I12: =LN(C12/C11) -> 0.043739207 | J12: =LN(D12/D11) -> -0.00049453455 | K12: =H12-(1-F12)*I12-F12*J12 -> 0.00081702039 | M12: =M11+K12 -> 0.098128767 | N12: =EXP(M12) -> 1.1031048
A13: 1958 | B13: =data!Y13 -> 1.42949 | C13: =data!AB13 -> 1.55376 | D13: =data!AE13 -> 1.13188 | F13: =F12 -> 0.56350243 | H13: =LN(B13/B12) -> -0.0072489845 | I13: =LN(C13/C12) -> 0.035752838 | J13: =LN(D13/D12) -> -0.03528384 | K13: =H13-(1-F13)*I13-F13*J13 -> -0.0029724816 | M13: =M12+K13 -> 0.095156286 | N13: =EXP(M13) -> 1.0998307
A14: 1959 | B14: =data!Y14 -> 1.52082 | C14: =data!AB14 -> 1.61254 | D14: =data!AE14 -> 1.17106 | F14: =F13 -> 0.56350243 | H14: =LN(B14/B13) -> 0.061931926 | I14: =LN(C14/C13) -> 0.037132776 | J14: =LN(D14/D13) -> 0.034029354 | K14: =H14-(1-F14)*I14-F14*J14 -> 0.026547935 | M14: =M13+K14 -> 0.12170422 | N14: =EXP(M14) -> 1.12942
... A72: 2017 | B72: =data!Y72 -> 8.18435 | C72: =data!AB72 -> 14.54005 | D72: =data!AE72 -> 2.77824 | F72: =F71 -> 0.56350243 | H72: =LN(B72/B71) -> 0.018785251 | I72: =LN(C72/C71) -> 0.051322072 | J72: =LN(D72/D71) -> 0.009816802 | K72: =H72-(1-F72)*I72-F72*J72 -> -0.0091485004 | M72: =M71+K72 -> 0.35796371 | N72: =EXP(M72) -> 1.4304137
L74: Log Diff (2017-1980) | N74: =LN(N72)-LN(N35) -> 0.1114395
L75: Exponential Growth Rate | N75: =N74/($A$72-$A$35) -> 0.0030118783

Sheet calA_X_TD
A1: year | B1: =data!K1 -> VA_TOT | C1: =data!AU1 -> X_TOT_P | D1: VA_TOT/X_P | E1: CAP_TOT_QI | F1: LAB_TOT_QI | H1: avg_LAB_S_TOT | J1: dl_chg_VA | K1: dl_chg_CAP | L1: dl_chg_LAB | M1: dl_chg_TFP | O1: Cum_Sum | P1: TFP_INDEX
A2: 1947 | B2: =data!K2 -> 244136 | C2: =data!AU2 -> 1 | D2: =B2/C2 -> 244136 | E2: =data!AB2 -> 1 | F2: =data!AE2 -> 1 | H2: =data!X74 -> 0.56350243 | O2: 0 | P2: =EXP(O2) -> 1
A3: 1948 | B3: =data!K3 -> 268064.5 | C3: =data!AU3 -> 1.0833 | D3: =B3/C3 -> 247451.77 | E3: =data!AB3 -> 1.03556 | F3: =data!AE3 -> 1.02442 | H3: =H2 -> 0.56350243 | J3: =LN(D3/D2) -> 0.013490238 | K3: =LN(E3/E2) -> 0.034942343 | L3: =LN(F3/F2) -> 0.024126599 | M3: =J3-(1-H3)*K3-H3*L3 -> -0.015357407 | O3: =O2+M3 -> -0.015357407 | P3: =EXP(O3) -> 0.98475992
A4: 1949 | B4: =data!K4 -> 266020.9 | C4: =data!AU4 -> 1.09984 | D4: =B4/C4 -> 241872.36 | E4: =data!AB4 -> 1.06183 | F4: =data!AE4 -> 0.98833 | H4: =H3 -> 0.56350243 | J4: =LN(D4/D3) -> -0.022805523 | K4: =LN(E4/E3) -> 0.025051491 | L4: =LN(F4/F3) -> -0.035865228 | M4: =J4-(1-H4)*K4-H4*L4 -> -0.013530295 | O4: =O3+M4 -> -0.028887702 | P4: =EXP(O4) -> 0.97152556
A5: 1950 | B5: =data!K5 -> 293337.2 | C5: =data!AU5 -> 1.11748 | D5: =B5/C5 -> 262498.84 | E5: =data!AB5 -> 1.09954 | F5: =data!AE5 -> 1.02903 | H5: =H4 -> 0.56350243 | J5: =LN(D5/D4) -> 0.081836488 | K5: =LN(E5/E4) -> 0.034898076 | L5: =LN(F5/F4) -> 0.04035524 | M5: =J5-(1-H5)*K5-H5*L5 -> 0.043863287 | O5: =O4+M5 -> 0.014975585 | P5: =EXP(O5) -> 1.0150883
A6: 1951 | B6: =data!K6 -> 339441.1 | C6: =data!AU6 -> 1.21932 | D6: =B6/C6 -> 278385.58 | E6: =data!AB6 -> 1.15156 | F6: =data!AE6 -> 1.09934 | H6: =H5 -> 0.56350243 | J6: =LN(D6/D5) -> 0.058760465 | K6: =LN(E6/E5) -> 0.046225634 | L6: =LN(F6/F5) -> 0.066093389 | M6: =J6-(1-H6)*K6-H6*L6 -> 0.0013393027 | O6: =O5+M6 -> 0.016314888 | P6: =EXP(O6) -> 1.0164487
A7: 1952 | B7: =data!K7 -> 359559.4 | C7: =data!AU7 -> 1.24767 | D7: =B7/C7 -> 288184.7 | E7: =data!AB7 -> 1.19948 | F7: =data!AE7 -> 1.1224 | H7: =H6 -> 0.56350243 | J7: =LN(D7/D6) -> 0.034594466 | K7: =LN(E7/E6) -> 0.040770585 | L7: =LN(F7/F6) -> 0.02075925 | M7: =J7-(1-H7)*K7-H7*L7 -> 0.0051003168 | O7: =O6+M7 -> 0.021415205 | P7: =EXP(O7) -> 1.0216462
A8: 1953 | B8: =data!K8 -> 380859.3 | C8: =data!AU8 -> 1.25009 | D8: =B8/C8 -> 304665.5 | E8: =data!AB8 -> 1.25268 | F8: =data!AE8 -> 1.14755 | H8: =H7 -> 0.56350243 | J8: =LN(D8/D7) -> 0.055612886 | K8: =LN(E8/E7) -> 0.043397127 | L8: =LN(F8/F7) -> 0.022159985 | M8: =J8-(1-H8)*K8-H8*L8 -> 0.02418294 | O8: =O7+M8 -> 0.045598144 | P8: =EXP(O8) -> 1.0466537
A9: 1954 | B9: =data!K9 -> 382379.5 | C9: =data!AU9 -> 1.2547 | D9: =B9/C9 -> 304757.71 | E9: =data!AB9 -> 1.3127 | F9: =data!AE9 -> 1.1093 | H9: =H8 -> 0.56350243 | J9: =LN(D9/D8) -> 0.00030260391 | K9: =LN(E9/E8) -> 0.046800829 | L9: =LN(F9/F8) -> -0.033900049 | M9: =J9-(1-H9)*K9-H9*L9 -> -0.001023084 | O9: =O8+M9 -> 0.04457506 | P9: =EXP(O9) -> 1.0455835
A10: 1955 | B10: =data!K10 -> 416129 | C10: =data!AU10 -> 1.2762 | D10: =B10/C10 -> 326068.8 | E10: =data!AB10 -> 1.36865 | F10: =data!AE10 -> 1.14721 | H10: =H9 -> 0.56350243 | J10: =LN(D10/D9) -> 0.067591325 | K10: =LN(E10/E9) -> 0.041738768 | L10: =LN(F10/F9) -> 0.033603722 | M10: =J10-(1-H10)*K10-H10*L10 -> 0.030436675 | O10: =O9+M10 -> 0.075011736 | P10: =EXP(O10) -> 1.0778968
A11: 1956 | B11: =data!K11 -> 439820.3 | C11: =data!AU11 -> 1.35706 | D11: =B11/C11 -> 324097.9 | E11: =data!AB11 -> 1.43503 | F11: =data!AE11 -> 1.17311 | H11: =H10 -> 0.56350243 | J11: =LN(D11/D10) -> -0.0060627565 | K11: =LN(E11/E10) -> 0.047360902 | L11: =LN(F11/F10) -> 0.022325434 | M11: =J11-(1-H11)*K11-H11*L11 -> -0.039316112 | O11: =O10+M11 -> 0.035695624 | P11: =EXP(O11) -> 1.0363404
A12: 1957 | B12: =data!K12 -> 463620.3 | C12: =data!AU12 -> 1.40622 | D12: =B12/C12 -> 329692.58 | E12: =data!AB12 -> 1.49919 | F12: =data!AE12 -> 1.17253 | H12: =H11 -> 0.56350243 | J12: =LN(D12/D11) -> 0.017115006 | K12: =LN(E12/E11) -> 0.043739207 | L12: =LN(F12/F11) -> -0.00049453455 | M12: =J12-(1-H12)*K12-H12*L12 -> -0.0016983809 | O12: =O11+M12 -> 0.033997243 | P12: =EXP(O12) -> 1.0345818
A13: 1958 | B13: =data!K13 -> 470428.9 | C13: =data!AU13 -> 1.41131 | D13: =B13/C13 -> 333327.83 | E13: =data!AB13 -> 1.55376 | F13: =data!AE13 -> 1.13188 | H13: =H12 -> 0.56350243 | J13: =LN(D13/D12) -> 0.010965836 | K13: =LN(E13/E12) -> 0.035752838 | L13: =LN(F13/F12) -> -0.03528384 | M13: =J13-(1-H13)*K13-H13*L13 -> 0.015242339 | O13: =O12+M13 -> 0.049239582 | P13: =EXP(O13) -> 1.050472
A14: 1959 | B14: =data!K14 -> 509054.2 | C14: =data!AU14 -> 1.42489 | D14: =B14/C14 -> 357258.6 | E14: =data!AB14 -> 1.61254 | F14: =data!AE14 -> 1.17106 | H14: =H13 -> 0.56350243 | J14: =LN(D14/D13) -> 0.069333396 | K14: =LN(E14/E13) -> 0.037132776 | L14: =LN(F14/F13) -> 0.034029354 | M14: =J14-(1-H14)*K14-H14*L14 -> 0.033949405 | O14: =O13+M14 -> 0.083188987 | P14: =EXP(O14) -> 1.0867472
... A72: 2017 | B72: =data!K72 -> 18810856 | C72: =data!AU72 -> 6.87951 | D72: =B72/C72 -> 2734330.8 | E72: =data!AB72 -> 14.54005 | F72: =data!AE72 -> 2.77824 | H72: =H71 -> 0.56350243 | J72: =LN(D72/D71) -> 0.025859256 | K72: =LN(E72/E71) -> 0.051322072 | L72: =LN(F72/F71) -> 0.009816802 | M72: =J72-(1-H72)*K72-H72*L72 -> -0.0020744951 | O72: =O71+M72 -> 0.67165647 | P72: =EXP(O72) -> 1.9574771
N74: Log Diff (2017-1980) | P74: =LN(P72)-LN(P35) -> 0.45347699
N75: Exponential Growth Rate | P75: =P74/($A$72-$A$35) -> 0.012256135

Sheet TFP_Goods
A1: year | B1: VA_GOOD_QI | C1: CAP_GOOD_QI | D1: LAB_GOOD_QI | F1: avg_LAB_S_TOT | H1: dl_chg_VA_QI | I1: dl_chg_CAP | J1: dl_chg_LAB | K1: dl_chg_TFP | M1: Cum_Sum | N1: TFP_INDEX
A2: 1947 | B2: =data!Z2 -> 1 | C2: =data!AC2 -> 1 | D2: =data!AF2 -> 1 | F2: =data!X74 -> 0.56350243 | M2: 0 | N2: =EXP(M2) -> 1
A3: 1948 | B3: =data!Z3 -> 1.08942 | C3: =data!AC3 -> 1.06134 | D3: =data!AF3 -> 1.01999 | F3: =F2 -> 0.56350243 | H3: =LN(B3/B2) -> 0.085645445 | I3: =LN(C3/C2) -> 0.059532261 | J3: =LN(D3/D2) -> 0.019792823 | K3: =H3-(1-F3)*I3-F3*J3 -> 0.048506453 | M3: =M2+K3 -> 0.048506453 | N3: =EXP(M3) -> 1.0497021
A4: 1949 | B4: =data!Z4 -> 1.05912 | C4: =data!AC4 -> 1.08348 | D4: =data!AF4 -> 0.95075 | F4: =F3 -> 0.56350243 | H4: =LN(B4/B3) -> -0.02820707 | I4: =LN(C4/C3) -> 0.020645822 | J4: =LN(D4/D3) -> -0.070296956 | K4: =H4-(1-F4)*I4-F4*J4 -> 0.0023935839 | M4: =M3+K4 -> 0.050900037 | N4: =EXP(M4) -> 1.0522177
A5: 1950 | B5: =data!Z5 -> 1.1729 | C5: =data!AC5 -> 1.12103 | D5: =data!AF5 -> 1.0109 | F5: =F4 -> 0.56350243 | H5: =LN(B5/B4) -> 0.10204094 | I5: =LN(C5/C4) -> 0.034069822 | J5: =LN(D5/D4) -> 0.061345155 | K5: =H5-(1-F5)*I5-F5*J5 -> 0.052601401 | M5: =M4+K5 -> 0.10350144 | N5: =EXP(M5) -> 1.1090474
A6: 1951 | B6: =data!Z6 -> 1.24522 | C6: =data!AC6 -> 1.19013 | D6: =data!AF6 -> 1.07845 | F6: =F5 -> 0.56350243 | H6: =LN(B6/B5) -> 0.059832907 | I6: =LN(C6/C5) -> 0.059814639 | J6: =LN(D6/D5) -> 0.064683802 | K6: =H6-(1-F6)*I6-F6*J6 -> -0.0027255177 | M6: =M5+K6 -> 0.10077592 | N6: =EXP(M6) -> 1.1060288
A7: 1952 | B7: =data!Z7 -> 1.30071 | C7: =data!AC7 -> 1.2408 | D7: =data!AF7 -> 1.0965 | F7: =F6 -> 0.56350243 | H7: =LN(B7/B6) -> 0.043598048 | I7: =LN(C7/C6) -> 0.041693788 | J7: =LN(D7/D6) -> 0.016598464 | K7: =H7-(1-F7)*I7-F7*J7 -> 0.016045536 | M7: =M6+K7 -> 0.11682146 | N7: =EXP(M7) -> 1.1239187
A8: 1953 | B8: =data!Z8 -> 1.39234 | C8: =data!AC8 -> 1.29971 | D8: =data!AF8 -> 1.12556 | F8: =F7 -> 0.56350243 | H8: =LN(B8/B7) -> 0.068075516 | I8: =LN(C8/C7) -> 0.04638483 | J8: =LN(D8/D7) -> 0.026157401 | K8: =H8-(1-F8)*I8-F8*J8 -> 0.033088891 | M8: =M7+K8 -> 0.14991035 | N8: =EXP(M8) -> 1.1617301
A9: 1954 | B9: =data!Z9 -> 1.35503 | C9: =data!AC9 -> 1.36591 | D9: =data!AF9 -> 1.05368 | F9: =F8 -> 0.56350243 | H9: =LN(B9/B8) -> -0.027162191 | I9: =LN(C9/C8) -> 0.049679711 | J9: =LN(D9/D8) -> -0.065991891 | K9: =H9-(1-F9)*I9-F9*J9 -> -0.011660673 | M9: =M8+K9 -> 0.13824968 | N9: =EXP(M9) -> 1.1482622
A10: 1955 | B10: =data!Z10 -> 1.48083 | C10: =data!AC10 -> 1.41756 | D10: =data!AF10 -> 1.10264 | F10: =F9 -> 0.56350243 | H10: =LN(B10/B9) -> 0.088779147 | I10: =LN(C10/C9) -> 0.037116211 | J10: =LN(D10/D9) -> 0.045418506 | K10: =H10-(1-F10)*I10-F10*J10 -> 0.046984573 | M10: =M9+K10 -> 0.18523425 | N10: =EXP(M10) -> 1.2035003
A11: 1956 | B11: =data!Z11 -> 1.48074 | C11: =data!AC11 -> 1.49208 | D11: =data!AF11 -> 1.1196 | F11: =F10 -> 0.56350243 | H11: =LN(B11/B10) -> -6.0778574e-05 | I11: =LN(C11/C10) -> 0.051234036 | J11: =LN(D11/D10) -> 0.015264174 | K11: =H11-(1-F11)*I11-F11*J11 -> -0.03102571 | M11: =M10+K11 -> 0.15420854 | N11: =EXP(M11) -> 1.1667342
A12: 1957 | B12: =data!Z12 -> 1.48555 | C12: =data!AC12 -> 1.56315 | D12: =data!AF12 -> 1.10034 | F12: =F11 -> 0.56350243 | H12: =LN(B12/B11) -> 0.0032431112 | I12: =LN(C12/C11) -> 0.046531896 | J12: =LN(D12/D11) -> -0.017352256 | K12: =H12-(1-F12)*I12-F12*J12 -> -0.0072899103 | M12: =M11+K12 -> 0.14691863 | N12: =EXP(M12) -> 1.1582597
A13: 1958 | B13: =data!Z13 -> 1.42265 | C13: =data!AC13 -> 1.60313 | D13: =data!AF13 -> 1.02297 | F13: =F12 -> 0.56350243 | H13: =LN(B13/B12) -> -0.043263744 | I13: =LN(C13/C12) -> 0.025254952 | J13: =LN(D13/D12) -> -0.072909062 | K13: =H13-(1-F13)*I13-F13*J13 -> -0.013203036 | M13: =M12+K13 -> 0.13371559 | N13: =EXP(M13) -> 1.1430677
A14: 1959 | B14: =data!Z14 -> 1.5251 | C14: =data!AC14 -> 1.63881 | D14: =data!AF14 -> 1.07984 | F14: =F13 -> 0.56350243 | H14: =LN(B14/B13) -> 0.069538652 | I14: =LN(C14/C13) -> 0.0220124 | J14: =LN(D14/D13) -> 0.054102721 | K14: =H14-(1-F14)*I14-F14*J14 -> 0.029443278 | M14: =M13+K14 -> 0.16315887 | N14: =EXP(M14) -> 1.1772237
... A72: 2017 | B72: =data!Z72 -> 5.99038 | C72: =data!AC72 -> 9.05806 | D72: =data!AF72 -> 1.3913 | F72: =F71 -> 0.56350243 | H72: =LN(B72/B71) -> 0.013454874 | I72: =LN(C72/C71) -> 0.0021196962 | J72: =LN(D72/D71) -> 0.010091719 | K72: =H72-(1-F72)*I72-F72*J72 -> 0.0068429231 | M72: =M71+K72 -> 0.64217458 | N72: =EXP(M72) -> 1.9006094
L74: Log Diff (2017-1980) | N74: =LN(N72/N35) -> 0.40265034
L75: Exponential Growth Rate | N75: =N74/($A$72-$A$35) -> 0.010882442

Sheet TFP_Serv
A1: year | B1: VA_SERV_QI | C1: CAP_SERV_QI | D1: LAB_SERV_QI | F1: avg_LAB_S_TOT | H1: dl_chg_VA | I1: dl_chg_CAP | J1: dl_chg_LAB | K1: dl_chg_TFP | M1: Cum_Sum | N1: TFP_INDEX
A2: 1947 | B2: =data!AA2 -> 1 | C2: =data!AD2 -> 1 | D2: =data!AG2 -> 1 | F2: =data!X74 -> 0.56350243 | M2: 0 | N2: =EXP(M2) -> 1
A3: 1948 | B3: =data!AA3 -> 1.00601 | C3: =data!AD3 -> 1.0219 | D3: =data!AG3 -> 1.02872 | F3: =F2 -> 0.56350243 | H3: =LN(B3/B2) -> 0.005992012 | I3: =LN(C3/C2) -> 0.02166364 | J3: =LN(D3/D2) -> 0.028315311 | K3: =H3-(1-F3)*I3-F3*J3 -> -0.019419861 | M3: =M2+K3 -> -0.019419861 | N3: =EXP(M3) -> 0.98076749
A4: 1949 | B4: =data!AA4 -> 1.01568 | C4: =data!AD4 -> 1.05031 | D4: =data!AG4 -> 1.02515 | F4: =F3 -> 0.56350243 | H4: =LN(B4/B3) -> 0.0095663269 | I4: =LN(C4/C3) -> 0.027421719 | J4: =LN(D4/D3) -> -0.0034763676 | K4: =H4-(1-F4)*I4-F4*J4 -> -0.00044424524 | M4: =M3+K4 -> -0.019864106 | N4: =EXP(M4) -> 0.98033189
A5: 1950 | B5: =data!AA5 -> 1.07752 | C5: =data!AD5 -> 1.08811 | D5: =data!AG5 -> 1.04729 | F5: =F4 -> 0.56350243 | H5: =LN(B5/B4) -> 0.059103765 | I5: =LN(C5/C4) -> 0.035356888 | J5: =LN(D5/D4) -> 0.021366932 | K5: =H5-(1-F5)*I5-F5*J5 -> 0.031630252 | M5: =M4+K5 -> 0.011766146 | N5: =EXP(M5) -> 1.0118356
A6: 1951 | B6: =data!AA6 -> 1.15292 | C6: =data!AD6 -> 1.13058 | D6: =data!AG6 -> 1.12034 | F6: =F5 -> 0.56350243 | H6: =LN(B6/B5) -> 0.06763575 | I6: =LN(C6/C5) -> 0.038288529 | J6: =LN(D6/D5) -> 0.067426335 | K6: =H6-(1-F6)*I6-F6*J6 -> 0.012927997 | M6: =M5+K6 -> 0.024694143 | N6: =EXP(M6) -> 1.0250016
A7: 1952 | B7: =data!AA7 -> 1.19085 | C7: =data!AD7 -> 1.177 | D7: =data!AG7 -> 1.14847 | F7: =F6 -> 0.56350243 | H7: =LN(B7/B6) -> 0.032369483 | I7: =LN(C7/C6) -> 0.040238053 | J7: =LN(D7/D6) -> 0.024798411 | K7: =H7-(1-F7)*I7-F7*J7 -> 0.00083170594 | M7: =M6+K7 -> 0.025525849 | N7: =EXP(M7) -> 1.0258544
A8: 1953 | B8: =data!AA8 -> 1.23335 | C8: =data!AD8 -> 1.22727 | D8: =data!AG8 -> 1.16965 | F8: =F7 -> 0.56350243 | H8: =LN(B8/B7) -> 0.035066707 | I8: =LN(C8/C7) -> 0.041823362 | J8: =LN(D8/D7) -> 0.018273937 | K8: =H8-(1-F8)*I8-F8*J8 -> 0.0065135027 | M8: =M7+K8 -> 0.032039351 | N8: =EXP(M8) -> 1.0325581
A9: 1954 | B9: =data!AA9 -> 1.2527 | C9: =data!AD9 -> 1.28423 | D9: =data!AG9 -> 1.16575 | F9: =F8 -> 0.56350243 | H9: =LN(B9/B8) -> 0.015567177 | I9: =LN(C9/C8) -> 0.045367127 | J9: =LN(D9/D8) -> -0.0033399021 | K9: =H9-(1-F9)*I9-F9*J9 -> -0.0023534202 | M9: =M8+K9 -> 0.029685931 | N9: =EXP(M9) -> 1.030131
A10: 1955 | B10: =data!AA10 -> 1.32621 | C10: =data!AD10 -> 1.34208 | D10: =data!AG10 -> 1.19271 | F10: =F9 -> 0.56350243 | H10: =LN(B10/B9) -> 0.057024028 | I10: =LN(C10/C9) -> 0.044061332 | J10: =LN(D10/D9) -> 0.022863372 | K10: =H10-(1-F10)*I10-F10*J10 -> 0.024907798 | M10: =M9+K10 -> 0.054593729 | N10: =EXP(M10) -> 1.0561115
A11: 1956 | B11: =data!AA11 -> 1.363 | C11: =data!AD11 -> 1.4044 | D11: =data!AG11 -> 1.22733 | F11: =F10 -> 0.56350243 | H11: =LN(B11/B10) -> 0.027362902 | I11: =LN(C11/C10) -> 0.045389516 | J11: =LN(D11/D10) -> 0.028613049 | K11: =H11-(1-F11)*I11-F11*J11 -> -0.0085730338 | M11: =M10+K11 -> 0.046020695 | N11: =EXP(M11) -> 1.0470961
A12: 1957 | B12: =data!AA12 -> 1.40555 | C12: =data!AD12 -> 1.46516 | D12: =data!AG12 -> 1.24481 | F12: =F11 -> 0.56350243 | H12: =LN(B12/B11) -> 0.030740533 | I12: =LN(C12/C11) -> 0.042354286 | J12: =LN(D12/D11) -> 0.01414183 | K12: =H12-(1-F12)*I12-F12*J12 -> 0.0042840341 | M12: =M11+K12 -> 0.050304729 | N12: =EXP(M12) -> 1.0515915
A13: 1958 | B13: =data!AA13 -> 1.42827 | C13: =data!AD13 -> 1.52604 | D13: =data!AG13 -> 1.23952 | F13: =F12 -> 0.56350243 | H13: =LN(B13/B12) -> 0.016035236 | I13: =LN(C13/C12) -> 0.040711693 | J13: =LN(D13/D12) -> -0.0042586999 | K13: =H13-(1-F13)*I13-F13*J13 -> 0.00066446891 | M13: =M12+K13 -> 0.050969198 | N13: =EXP(M13) -> 1.0522905
A14: 1959 | B14: =data!AA14 -> 1.51228 | C14: =data!AD14 -> 1.59466 | D14: =data!AG14 -> 1.26179 | F14: =F13 -> 0.56350243 | H14: =LN(B14/B13) -> 0.057154524 | I14: =LN(C14/C13) -> 0.043984403 | J14: =LN(D14/D13) -> 0.01780714 | K14: =H14-(1-F14)*I14-F14*J14 -> 0.027921073 | M14: =M13+K14 -> 0.078890271 | N14: =EXP(M14) -> 1.0820856
... A72: 2017 | B72: =data!AA72 -> 9.28016 | C72: =data!AD72 -> 16.78096 | D72: =data!AG72 -> 3.88789 | F72: =F71 -> 0.56350243 | H72: =LN(B72/B71) -> 0.020120991 | I72: =LN(C72/C71) -> 0.063852264 | J72: =LN(D72/D71) -> 0.0097440963 | K72: =H72-(1-F72)*I72-F72*J72 -> -0.013241189 | M72: =M71+K72 -> 0.23168761 | N72: =EXP(M72) -> 1.2607258
L74: Log Diff (2017-1980) | N74: =LN(N72/N35) -> 0.013883591
L75: Exponential Growth Rate | N75: =N74/($A$72-$A$35) -> 0.00037523218

Sheet TFP_Tot_Lequals1
A1: year | B1: VA_TOT_QI | C1: CAP_TOT_QI | D1: LAB_TOT_QI | F1: avg_LAB_S_TOT | H1: dl_chg_VA | I1: dl_chg_CAP | J1: dl_chg_TFP | L1: Cum_Sum | M1: TFP_INDEX
A2: 1947 | B2: =data!Y2 -> 1 | C2: =data!AB2 -> 1 | D2: =data!AE2 -> 1 | F2: =+data!X74 -> 0.56350243 | L2: 0 | M2: =EXP(L2) -> 1
A3: 1948 | B3: =data!Y3 -> 1.0406 | C3: =data!AB3 -> 1.03556 | D3: =data!AE3 -> 1.02442 | F3: =F2 -> 0.56350243 | H3: =LN(B3/B2) -> 0.03979747 | I3: =LN(C3/C2) -> 0.034942343 | J3: =H3-(1-F3)*I3 -> 0.024545222 | L3: =L2+J3 -> 0.024545222 | M3: =EXP(L3) -> 1.0248489
A4: 1949 | B4: =data!Y4 -> 1.03397 | C4: =data!AB4 -> 1.06183 | D4: =data!AE4 -> 0.98833 | F4: =F3 -> 0.56350243 | H4: =LN(B4/B3) -> -0.0063917077 | I4: =LN(C4/C3) -> 0.025051491 | J4: =H4-(1-F4)*I4 -> -0.017326623 | L4: =L3+J4 -> 0.007218599 | M4: =EXP(L4) -> 1.0072447
A5: 1950 | B5: =data!Y5 -> 1.1168 | C5: =data!AB5 -> 1.09954 | D5: =data!AE5 -> 1.02903 | F5: =F4 -> 0.56350243 | H5: =LN(B5/B4) -> 0.077061691 | I5: =LN(C5/C4) -> 0.034898076 | J5: =H5-(1-F5)*I5 -> 0.061828766 | L5: =L4+J5 -> 0.069047365 | M5: =EXP(L5) -> 1.071487
A6: 1951 | B6: =data!Y6 -> 1.19094 | C6: =data!AB6 -> 1.15156 | D6: =data!AE6 -> 1.09934 | F6: =F5 -> 0.56350243 | H6: =LN(B6/B5) -> 0.064275458 | I6: =LN(C6/C5) -> 0.046225634 | J6: =H6-(1-F6)*I6 -> 0.044098081 | L6: =L5+J6 -> 0.11314545 | M6: =EXP(L6) -> 1.1197948
A7: 1952 | B7: =data!Y7 -> 1.23605 | C7: =data!AB7 -> 1.19948 | D7: =data!AE7 -> 1.1224 | F7: =F6 -> 0.56350243 | H7: =LN(B7/B6) -> 0.0371779 | I7: =LN(C7/C6) -> 0.040770585 | J7: =H7-(1-F7)*I7 -> 0.019381639 | L7: =L6+J7 -> 0.13252708 | M7: =EXP(L7) -> 1.1417099
A8: 1953 | B8: =data!Y8 -> 1.29813 | C8: =data!AB8 -> 1.25268 | D8: =data!AE8 -> 1.14755 | F8: =F7 -> 0.56350243 | H8: =LN(B8/B7) -> 0.049003956 | I8: =LN(C8/C7) -> 0.043397127 | J8: =H8-(1-F8)*I8 -> 0.030061216 | L8: =L7+J8 -> 0.1625883 | M8: =EXP(L8) -> 1.1765522
A9: 1954 | B9: =data!Y9 -> 1.29535 | C9: =data!AB9 -> 1.3127 | D9: =data!AE9 -> 1.1093 | F9: =F8 -> 0.56350243 | H9: =LN(B9/B8) -> -0.0021438384 | I9: =LN(C9/C8) -> 0.046800829 | J9: =H9-(1-F9)*I9 -> -0.022572286 | L9: =L8+J9 -> 0.14001601 | M9: =EXP(L9) -> 1.1502922
A10: 1955 | B10: =data!Y10 -> 1.38929 | C10: =data!AB10 -> 1.36865 | D10: =data!AE10 -> 1.14721 | F10: =F9 -> 0.56350243 | H10: =LN(B10/B9) -> 0.070011896 | I10: =LN(C10/C9) -> 0.041738768 | J10: =H10-(1-F10)*I10 -> 0.051793026 | L10: =L9+J10 -> 0.19180904 | M10: =EXP(L10) -> 1.2114392
A11: 1956 | B11: =data!Y11 -> 1.4119 | C11: =data!AB11 -> 1.43503 | D11: =data!AE11 -> 1.17311 | F11: =F10 -> 0.56350243 | H11: =LN(B11/B10) -> 0.01614349 | I11: =LN(C11/C10) -> 0.047360902 | J11: =H11-(1-F11)*I11 -> -0.0045294291 | L11: =L10+J11 -> 0.18727961 | M11: =EXP(L11) -> 1.2059644
A12: 1957 | B12: =data!Y12 -> 1.43989 | C12: =data!AB12 -> 1.49919 | D12: =data!AE12 -> 1.17253 | F12: =F11 -> 0.56350243 | H12: =LN(B12/B11) -> 0.019630407 | I12: =LN(C12/C11) -> 0.043739207 | J12: =H12-(1-F12)*I12 -> 0.00053834897 | L12: =L11+J12 -> 0.18781796 | M12: =EXP(L12) -> 1.2066138
A13: 1958 | B13: =data!Y13 -> 1.42949 | C13: =data!AB13 -> 1.55376 | D13: =data!AE13 -> 1.13188 | F13: =F12 -> 0.56350243 | H13: =LN(B13/B12) -> -0.0072489845 | I13: =LN(C13/C12) -> 0.035752838 | J13: =H13-(1-F13)*I13 -> -0.022855011 | L13: =L12+J13 -> 0.16496295 | M13: =EXP(L13) -> 1.1793494
A14: 1959 | B14: =data!Y14 -> 1.52082 | C14: =data!AB14 -> 1.61254 | D14: =data!AE14 -> 1.17106 | F14: =F13 -> 0.56350243 | H14: =LN(B14/B13) -> 0.061931926 | I14: =LN(C14/C13) -> 0.037132776 | J14: =H14-(1-F14)*I14 -> 0.045723559 | L14: =L13+J14 -> 0.21068651 | M14: =EXP(L14) -> 1.2345253
... A72: 2017 | B72: =data!Y72 -> 8.18435 | C72: =data!AB72 -> 14.54005 | D72: =data!AE72 -> 2.77824 | F72: =F71 -> 0.56350243 | H72: =LN(B72/B71) -> 0.018785251 | I72: =LN(C72/C71) -> 0.051322072 | J72: =H72-(1-F72)*I72 -> -0.0036167087 | L72: =L71+J72 -> 0.93376043 | M72: =EXP(L72) -> 2.544058
K74: Log Diff (2017-1980) | M74: =LN(M72)-LN(M35) -> 0.40101562
K75: Exponential Growth Rate | M75: =M74/($A$72-$A$35) -> 0.01083826

Sheet calA_X_TD_Lequals1
A1: year | B1: =data!K1 -> VA_TOT | C1: =data!AU1 -> X_TOT_P | D1: VA_TOT/X_P | E1: CAP_TOT_QI | F1: LAB_TOT_QI | H1: avg_LAB_S_TOT | J1: dl_chg_VA | K1: dl_chg_CAP | L1: dl_chg_TFP | N1: Cum_Sum | O1: TFP_INDEX
A2: 1947 | B2: =data!K2 -> 244136 | C2: =data!AU2 -> 1 | D2: =B2/C2 -> 244136 | E2: =data!AB2 -> 1 | F2: =data!AE2 -> 1 | H2: =data!X74 -> 0.56350243 | N2: 0 | O2: =EXP(N2) -> 1
A3: 1948 | B3: =data!K3 -> 268064.5 | C3: =data!AU3 -> 1.0833 | D3: =B3/C3 -> 247451.77 | E3: =data!AB3 -> 1.03556 | F3: =data!AE3 -> 1.02442 | H3: =H2 -> 0.56350243 | J3: =LN(D3/D2) -> 0.013490238 | K3: =LN(E3/E2) -> 0.034942343 | L3: =J3-(1-H3)*K3 -> -0.0017620098 | N3: =N2+L3 -> -0.0017620098 | O3: =EXP(N3) -> 0.99823954
A4: 1949 | B4: =data!K4 -> 266020.9 | C4: =data!AU4 -> 1.09984 | D4: =B4/C4 -> 241872.36 | E4: =data!AB4 -> 1.06183 | F4: =data!AE4 -> 0.98833 | H4: =H3 -> 0.56350243 | J4: =LN(D4/D3) -> -0.022805523 | K4: =LN(E4/E3) -> 0.025051491 | L4: =J4-(1-H4)*K4 -> -0.033740438 | N4: =N3+L4 -> -0.035502448 | O4: =EXP(N4) -> 0.96512037
A5: 1950 | B5: =data!K5 -> 293337.2 | C5: =data!AU5 -> 1.11748 | D5: =B5/C5 -> 262498.84 | E5: =data!AB5 -> 1.09954 | F5: =data!AE5 -> 1.02903 | H5: =H4 -> 0.56350243 | J5: =LN(D5/D4) -> 0.081836488 | K5: =LN(E5/E4) -> 0.034898076 | L5: =J5-(1-H5)*K5 -> 0.066603562 | N5: =N4+L5 -> 0.031101115 | O5: =EXP(N5) -> 1.0315898
A6: 1951 | B6: =data!K6 -> 339441.1 | C6: =data!AU6 -> 1.21932 | D6: =B6/C6 -> 278385.58 | E6: =data!AB6 -> 1.15156 | F6: =data!AE6 -> 1.09934 | H6: =H5 -> 0.56350243 | J6: =LN(D6/D5) -> 0.058760465 | K6: =LN(E6/E5) -> 0.046225634 | L6: =J6-(1-H6)*K6 -> 0.038583088 | N6: =N5+L6 -> 0.069684203 | O6: =EXP(N6) -> 1.0721695
A7: 1952 | B7: =data!K7 -> 359559.4 | C7: =data!AU7 -> 1.24767 | D7: =B7/C7 -> 288184.7 | E7: =data!AB7 -> 1.19948 | F7: =data!AE7 -> 1.1224 | H7: =H6 -> 0.56350243 | J7: =LN(D7/D6) -> 0.034594466 | K7: =LN(E7/E6) -> 0.040770585 | L7: =J7-(1-H7)*K7 -> 0.016798205 | N7: =N6+L7 -> 0.086482407 | O7: =EXP(N7) -> 1.0903322
A8: 1953 | B8: =data!K8 -> 380859.3 | C8: =data!AU8 -> 1.25009 | D8: =B8/C8 -> 304665.5 | E8: =data!AB8 -> 1.25268 | F8: =data!AE8 -> 1.14755 | H8: =H7 -> 0.56350243 | J8: =LN(D8/D7) -> 0.055612886 | K8: =LN(E8/E7) -> 0.043397127 | L8: =J8-(1-H8)*K8 -> 0.036670145 | N8: =N7+L8 -> 0.12315255 | O8: =EXP(N8) -> 1.131057
A9: 1954 | B9: =data!K9 -> 382379.5 | C9: =data!AU9 -> 1.2547 | D9: =B9/C9 -> 304757.71 | E9: =data!AB9 -> 1.3127 | F9: =data!AE9 -> 1.1093 | H9: =H8 -> 0.56350243 | J9: =LN(D9/D8) -> 0.00030260391 | K9: =LN(E9/E8) -> 0.046800829 | L9: =J9-(1-H9)*K9 -> -0.020125844 | N9: =N8+L9 -> 0.10302671 | O9: =EXP(N9) -> 1.108521
A10: 1955 | B10: =data!K10 -> 416129 | C10: =data!AU10 -> 1.2762 | D10: =B10/C10 -> 326068.8 | E10: =data!AB10 -> 1.36865 | F10: =data!AE10 -> 1.14721 | H10: =H9 -> 0.56350243 | J10: =LN(D10/D9) -> 0.067591325 | K10: =LN(E10/E9) -> 0.041738768 | L10: =J10-(1-H10)*K10 -> 0.049372454 | N10: =N9+L10 -> 0.15239916 | O10: =EXP(N10) -> 1.164625
A11: 1956 | B11: =data!K11 -> 439820.3 | C11: =data!AU11 -> 1.35706 | D11: =B11/C11 -> 324097.9 | E11: =data!AB11 -> 1.43503 | F11: =data!AE11 -> 1.17311 | H11: =H10 -> 0.56350243 | J11: =LN(D11/D10) -> -0.0060627565 | K11: =LN(E11/E10) -> 0.047360902 | L11: =J11-(1-H11)*K11 -> -0.026735675 | N11: =N10+L11 -> 0.12566349 | O11: =EXP(N11) -> 1.1339005
A12: 1957 | B12: =data!K12 -> 463620.3 | C12: =data!AU12 -> 1.40622 | D12: =B12/C12 -> 329692.58 | E12: =data!AB12 -> 1.49919 | F12: =data!AE12 -> 1.17253 | H12: =H11 -> 0.56350243 | J12: =LN(D12/D11) -> 0.017115006 | K12: =LN(E12/E11) -> 0.043739207 | L12: =J12-(1-H12)*K12 -> -0.0019770523 | N12: =N11+L12 -> 0.12368644 | O12: =EXP(N12) -> 1.131661
A13: 1958 | B13: =data!K13 -> 470428.9 | C13: =data!AU13 -> 1.41131 | D13: =B13/C13 -> 333327.83 | E13: =data!AB13 -> 1.55376 | F13: =data!AE13 -> 1.13188 | H13: =H12 -> 0.56350243 | J13: =LN(D13/D12) -> 0.010965836 | K13: =LN(E13/E12) -> 0.035752838 | L13: =J13-(1-H13)*K13 -> -0.0046401909 | N13: =N12+L13 -> 0.11904624 | O13: =EXP(N13) -> 1.126422
A14: 1959 | B14: =data!K14 -> 509054.2 | C14: =data!AU14 -> 1.42489 | D14: =B14/C14 -> 357258.6 | E14: =data!AB14 -> 1.61254 | F14: =data!AE14 -> 1.17106 | H14: =H13 -> 0.56350243 | J14: =LN(D14/D13) -> 0.069333396 | K14: =LN(E14/E13) -> 0.037132776 | L14: =J14-(1-H14)*K14 -> 0.053125029 | N14: =N13+L14 -> 0.17217127 | O14: =EXP(N14) -> 1.1878813
... A72: 2017 | B72: =data!K72 -> 18810856 | C72: =data!AU72 -> 6.87951 | D72: =B72/C72 -> 2734330.8 | E72: =data!AB72 -> 14.54005 | F72: =data!AE72 -> 2.77824 | H72: =H71 -> 0.56350243 | J72: =LN(D72/D71) -> 0.025859256 | K72: =LN(E72/E71) -> 0.051322072 | L72: =J72-(1-H72)*K72 -> 0.0034572967 | N72: =N71+L72 -> 1.2474532 | O72: =EXP(N72) -> 3.481465
M74: Log Diff (2017-1980) | O74: =LN(O72)-LN(O35) -> 0.74305311
M75: Exponential Growth Rate | O75: =O74/($A$72-$A$35) -> 0.020082516

Sheet TFP_Goods_Lequals1
A1: year | B1: VA_GOOD_QI | C1: CAP_GOOD_QI | D1: LAB_GOOD_QI | F1: avg_LAB_S_TOT | H1: LAB_TOT | I1: LAB_GOOD | J1: LAB_SERV | K1: EMP_SHARE_GOODS | M1: dl_chg_VA_QI | N1: dl_chg_CAP | O1: dl_chg_LAB | P1: dl_chg_TFP | R1: Cum_Sum | S1: TFP_INDEX
A2: 1947 | B2: =data!Z2 -> 1 | C2: =data!AC2 -> 1 | D2: =data!AF2 -> 1 | F2: =+data!X74 -> 0.56350243 | H2: =data!U2 -> 128228.3 | I2: =data!V2 -> 62056.7 | J2: =data!W2 -> 66171.6 | K2: =I2/H2 -> 0.48395479 | R2: 0 | S2: =EXP(R2) -> 1
A3: 1948 | B3: =data!Z3 -> 1.08942 | C3: =data!AC3 -> 1.06134 | D3: =data!AF3 -> 1.01999 | F3: =F2 -> 0.56350243 | H3: =data!U3 -> 141262.3 | I3: =data!V3 -> 70286.9 | J3: =data!W3 -> 70975.4 | K3: =I3/H3 -> 0.49756304 | M3: =LN(B3/B2) -> 0.085645445 | N3: =LN(C3/C2) -> 0.059532261 | O3: =LN(K3/K2) -> 0.027730777 | P3: =M3-(1-F3)*N3-F3*O3 -> 0.044033397 | R3: =R2+P3 -> 0.044033397 | S3: =EXP(R3) -> 1.0450173
A4: 1949 | B4: =data!Z4 -> 1.05912 | C4: =data!AC4 -> 1.08348 | D4: =data!AF4 -> 0.95075 | F4: =F3 -> 0.56350243 | H4: =data!U4 -> 144455.8 | I4: =data!V4 -> 68189.2 | J4: =data!W4 -> 76266.5 | K4: =I4/H4 -> 0.47204197 | M4: =LN(B4/B3) -> -0.02820707 | N4: =LN(C4/C3) -> 0.020645822 | O4: =LN(K4/K3) -> -0.052654375 | P4: =M4-(1-F4)*N4-F4*O4 -> -0.0075480529 | R4: =R3+P4 -> 0.036485344 | S4: =EXP(R4) -> 1.0371591
A5: 1950 | B5: =data!Z5 -> 1.1729 | C5: =data!AC5 -> 1.12103 | D5: =data!AF5 -> 1.0109 | F5: =F4 -> 0.56350243 | H5: =data!U5 -> 153536.1 | I5: =data!V5 -> 73332.3 | J5: =data!W5 -> 80203.8 | K5: =I5/H5 -> 0.47762253 | M5: =LN(B5/B4) -> 0.10204094 | N5: =LN(C5/C4) -> 0.034069822 | O5: =LN(K5/K4) -> 0.011752832 | P5: =M5-(1-F5)*N5-F5*O5 -> 0.080546796 | R5: =R4+P5 -> 0.11703214 | S5: =EXP(R5) -> 1.1241556
A6: 1951 | B6: =data!Z6 -> 1.24522 | C6: =data!AC6 -> 1.19013 | D6: =data!AF6 -> 1.07845 | F6: =F5 -> 0.56350243 | H6: =data!U6 -> 174406.8 | I6: =data!V6 -> 86367.1 | J6: =data!W6 -> 88039.7 | K6: =I6/H6 -> 0.49520489 | M6: =LN(B6/B5) -> 0.059832907 | N6: =LN(C6/C5) -> 0.059814639 | O6: =LN(K6/K5) -> 0.036150867 | P6: =M6-(1-F6)*N6-F6*O6 -> 0.013352861 | R6: =R5+P6 -> 0.130385 | S6: =EXP(R6) -> 1.1392669
A7: 1952 | B7: =data!Z7 -> 1.30071 | C7: =data!AC7 -> 1.2408 | D7: =data!AF7 -> 1.0965 | F7: =F6 -> 0.56350243 | H7: =data!U7 -> 184289.9 | I7: =data!V7 -> 90294.4 | J7: =data!W7 -> 93995.5 | K7: =I7/H7 -> 0.48995848 | M7: =LN(B7/B6) -> 0.043598048 | N7: =LN(C7/C6) -> 0.041693788 | O7: =LN(K7/K6) -> -0.010650933 | P7: =M7-(1-F7)*N7-F7*O7 -> 0.031400637 | R7: =R6+P7 -> 0.16178564 | S7: =EXP(R7) -> 1.1756082
A8: 1953 | B8: =data!Z8 -> 1.39234 | C8: =data!AC8 -> 1.29971 | D8: =data!AF8 -> 1.12556 | F8: =F7 -> 0.56350243 | H8: =data!U8 -> 202171.1 | I8: =data!V8 -> 100464.4 | J8: =data!W8 -> 101706.7 | K8: =I8/H8 -> 0.4969276 | M8: =LN(B8/B7) -> 0.068075516 | N8: =LN(C8/C7) -> 0.04638483 | O8: =LN(K8/K7) -> 0.014123686 | P8: =M8-(1-F8)*N8-F8*O8 -> 0.039869919 | R8: =R7+P8 -> 0.20165556 | S8: =EXP(R8) -> 1.2234265
A9: 1954 | B9: =data!Z9 -> 1.35503 | C9: =data!AC9 -> 1.36591 | D9: =data!AF9 -> 1.05368 | F9: =F8 -> 0.56350243 | H9: =data!U9 -> 197065.8 | I9: =data!V9 -> 94278.4 | J9: =data!W9 -> 102787.3 | K9: =I9/H9 -> 0.47841076 | M9: =LN(B9/B8) -> -0.027162191 | N9: =LN(C9/C8) -> 0.049679711 | O9: =LN(K9/K8) -> -0.037974643 | P9: =M9-(1-F9)*N9-F9*O9 -> -0.02744846 | R9: =R8+P9 -> 0.1742071 | S9: =EXP(R9) -> 1.190302
A10: 1955 | B10: =data!Z10 -> 1.48083 | C10: =data!AC10 -> 1.41756 | D10: =data!AF10 -> 1.10264 | F10: =F9 -> 0.56350243 | H10: =data!U10 -> 222725.8 | I10: =data!V10 -> 105471.1 | J10: =data!W10 -> 117254.6 | K10: =I10/H10 -> 0.47354685 | M10: =LN(B10/B9) -> 0.088779147 | N10: =LN(C10/C9) -> 0.037116211 | O10: =LN(K10/K9) -> -0.010218861 | P10: =M10-(1-F10)*N10-F10*O10 -> 0.078336364 | R10: =R9+P10 -> 0.25254346 | S10: =EXP(R10) -> 1.2872954
